Workbook

Sheet 현황
A1: Restful-booker API 테스트 케이스 · 테스트 현황 보고서
A3: 1. 개요 및 최종 업데이트
A4: 구분 | B4: 내용
A5: 프로젝트 명 | B5: Restful-booker API 테스트 (학습용)
A6: 대상 API | B6: https://restful-booker.herokuapp.com/apidoc/index.html ({{baseUrl}} = https://restful-booker.herokuapp.com)
A7: 저장소 | B7: https://github.com/IWlastnameisKim/api-test-restful-booker
A8: 테스트 방식 | B8: Postman + Newman 데이터 기반 테스트. 공통 절차는 템플릿 시트, 입력값은 데이터셋 시트
A9: 케이스 원본 | B9: data/*.json 데이터 파일 (id, case, purpose, expectedStatus, body). 데이터셋 시트의 ID·케이스·목적·입력·기대 Status는 데이터 파일과 같아야 함
A10: 문서 버전 | B10: v1.2
A11: 테스트 실행일 | B11: 2026-10-27
A12: 최종 업데이트 | B12: 2026-10-28
A13: QA 담당자 | B13: InWon Kim
A15: 2. 템플릿별 테스트 현황
A16: NO | B16: 템플릿 | C16: 전체 Case | D16: PASS | E16: FAIL | F16: BLOCK | G16: Not Tested | H16: N/A | I16: 진행률 | J16: 성공률
A17: 1 | B17: BKG-POST (예약 생성) | C17: =COUNTA(예약생성_데이터!$A$2:$A$10) -> 9 | D17: =COUNTIF(예약생성_데이터!$M$2:$M$10,"PASS") -> 2 | E17: =COUNTIF(예약생성_데이터!$M$2:$M$10,"FAIL") -> 7 | F17: =COUNTIF(예약생성_데이터!$M$2:$M$10,"BLOCK") -> 0 | G17: =COUNTIF(예약생성_데이터!$M$2:$M$10,"Not Tested")+COUNTBLANK(예약생성_데이터!$M$2:$M$10) -> 0 | H17: =COUNTIF(예약생성_데이터!$M$2:$M$10,"N/A") -> 0 | I17: =IF(C17=0,0,(C17-G17)/C17) -> 1 | J17: =IF((C17-G17-H17)=0,0,D17/(C17-G17-H17)) -> 0.22222222
A18: 2 | B18: BKG-PATCH (부분 수정) | C18: =COUNTA(부분수정_데이터!$A$2:$A$34) -> 33 | D18: =COUNTIF(부분수정_데이터!$M$2:$M$34,"PASS") -> 9 | E18: =COUNTIF(부분수정_데이터!$M$2:$M$34,"FAIL") -> 24 | F18: =COUNTIF(부분수정_데이터!$M$2:$M$34,"BLOCK") -> 0 | G18: =COUNTIF(부분수정_데이터!$M$2:$M$34,"Not Tested")+COUNTBLANK(부분수정_데이터!$M$2:$M$34) -> 0 | H18: =COUNTIF(부분수정_데이터!$M$2:$M$34,"N/A") -> 0 | I18: =IF(C18=0,0,(C18-G18)/C18) -> 1 | J18: =IF((C18-G18-H18)=0,0,D18/(C18-G18-H18)) -> 0.27272727
B19: 총계 | C19: =SUM(C17:C18) -> 42 | D19: =SUM(D17:D18) -> 11 | E19: =SUM(E17:E18) -> 31 | F19: =SUM(F17:F18) -> 0 | G19: =SUM(G17:G18) -> 0 | H19: =SUM(H17:H18) -> 0 | I19: =IF(C19=0,0,(C19-G19)/C19) -> 1 | J19: =IF((C19-G19-H19)=0,0,D19/(C19-G19-H19)) -> 0.26190476
A20: 진행률 = (전체 - Not Tested) / 전체 · 성공률 = PASS / (전체 - Not Tested - N/A). 결과 칸이 비어 있으면 Not Tested로 집계
A22: 3. 결함 현황 (심각도별)
A23: 심각도 | B23: 전체 건수 | C23: 조치 완료 (Fixed/Closed) | D23: 미조치 (Open)
A24: 상 | B24: =COUNTIF(결함목록!$E$2:$E$22,A24) -> 13 | C24: =COUNTIFS(결함목록!$E$2:$E$22,A24,결함목록!$F$2:$F$22,"Fixed")+COUNTIFS(결함목록!$E$2:$E$22,A24,결함목록!$F$2:$F$22,"Closed") -> 0 | D24: =COUNTIFS(결함목록!$E$2:$E$22,A24,결함목록!$F$2:$F$22,"Open") -> 13
A25: 중 | B25: =COUNTIF(결함목록!$E$2:$E$22,A25) -> 5 | C25: =COUNTIFS(결함목록!$E$2:$E$22,A25,결함목록!$F$2:$F$22,"Fixed")+COUNTIFS(결함목록!$E$2:$E$22,A25,결함목록!$F$2:$F$22,"Closed") -> 0 | D25: =COUNTIFS(결함목록!$E$2:$E$22,A25,결함목록!$F$2:$F$22,"Open") -> 5
A26: 하 | B26: =COUNTIF(결함목록!$E$2:$E$22,A26) -> 1 | C26: =COUNTIFS(결함목록!$E$2:$E$22,A26,결함목록!$F$2:$F$22,"Fixed")+COUNTIFS(결함목록!$E$2:$E$22,A26,결함목록!$F$2:$F$22,"Closed") -> 0 | D26: =COUNTIFS(결함목록!$E$2:$E$22,A26,결함목록!$F$2:$F$22,"Open") -> 1
A27: 정책 확인 | B27: =COUNTIF(결함목록!$E$2:$E$22,A27) -> 2 | C27: =COUNTIFS(결함목록!$E$2:$E$22,A27,결함목록!$F$2:$F$22,"Fixed")+COUNTIFS(결함목록!$E$2:$E$22,A27,결함목록!$F$2:$F$22,"Closed") -> 0 | D27: =COUNTIFS(결함목록!$E$2:$E$22,A27,결함목록!$F$2:$F$22,"Open") -> 2
A28: 총계 | B28: =SUM(B24:B27) -> 21 | C28: =SUM(C24:C27) -> 0 | D28: =SUM(D24:D27) -> 21
A30: 4. 특이사항
A31: 1 | B31: PATCH에는 입력 검증이 없어 거절돼야 할 요청 23건이 모두 200을 반환함
A32: 2 | B32: P-1·P-2: 명세대로 일부 필드만 보낸 정상 요청에서 보내지 않은 날짜가 0NaN-aN-aN으로 깨짐
A33: 3 | B33: P-13: depositpaid 문자열 처리(400 거절 vs 무시 후 200)는 정책 결정 필요. 원본이 true라 현재 케이스로는 무시와 변환이 구분되지 않음
A35: 5. 문서 구성과 항목 정의
A36: 항목 | B36: 설명
A37: 템플릿 시트 | B37: data-driven 테스트 1개 = 템플릿 1행. 공통 사전조건, 요청(Method·Endpoint·Headers), 판정 기준, 데이터 파일, 자동화 위치를 한 번만 기재
A38: 데이터셋 시트 | B38: 데이터 파일 1행 = 케이스 1행. 템플릿 열로 어느 템플릿의 입력인지 연결하고, 행마다 다른 입력·기대·실제·결과만 기재
A39: ID | B39: BKG-POST-nnn / BKG-PATCH-nnn. 데이터 파일의 id와 같음. 테스트 이름에 넣으면 Newman 리포트와 연결됨
A40: 분류 / 대상 | B40: 검증 유형(정상·타입·범위·날짜·요청 형식)과 대상 필드·조건
A41: 입력 body | B41: {{requestBody}}에 들어가는 행의 body 원문
A42: 기대 Status / 기대 Response / 기대 저장값 | B42: 명세 기준의 올바른 응답과, 재조회했을 때 저장돼 있어야 할 값
A43: 실제 Status / 실제 Response | B43: 실행 시 관찰한 응답 코드와 응답·저장값
A44: 결과 | B44: PASS / FAIL / BLOCK / N/A / Not Tested
A45: 결함 ID / 비고 | B45: 결함목록 시트의 ID, 정책 확인 사항
...

Sheet 템플릿
A1: 템플릿 ID | B1: 대상 | C1: 테스트 목적 | D1: 사전조건 | E1: Method | F1: Endpoint | G1: Headers | H1: Request Body | I1: 판정 기준 (응답) | J1: 검증 요청 | K1: 판정 기준 (저장값) | L1: 데이터 파일 | M1: 데이터셋 시트 | N1: 케이스 수 | O1: Postman 위치 | P1: Before request | Q1: After response | R1: 실행 명령
A2: BKG-POST | B2: 예약 생성 (POST) | C2: 예약 생성 시 필드별 입력값 검증이 명세대로 동작하는지 확인 | D2: 1. baseUrl 접근 가능 2. 인증 불필요 (예약 생성은 토큰 없이 가능) | E2: POST | F2: {{baseUrl}}/booking | G2: Content-Type: application/json Accept: application/json | H2: {{requestBody}} = 데이터셋의 입력 body | I2: 상태 코드 == 데이터셋의 기대 Status | J2: 없음 (응답만 판정) | K2: - | L2: data/booking-cases.json | M2: 예약생성_데이터 | N2: =COUNTA(예약생성_데이터!$A$2:$A$200) -> 9 | O2: 06-Data-Driven > booking - 입력값 검증 | P2: 행의 body → JSON.stringify → requestBody 변수 저장. 데이터 없이 실행되면 안내 로그 | Q2: 상태 코드 == expectedStatus 판정. 다르면 보낸 body와 응답 전체를 로그로 기록 | R2: npm run test:data
A3: BKG-PATCH | B3: 부분 수정 (PATCH) | C3: 부분 수정 시 보낸 필드만 바뀌고, 잘못된 입력은 거절되어 원본이 유지되는지 확인 | D3: 1. POST /auth로 토큰 발급 ({{username}} / {{password}}) 2. POST /booking으로 행마다 새 예약 생성 후 bookingid 확보 - 원본: firstname POST, lastname PATCH, totalprice 2300, depositpaid true, checkin 2018-01-01, checkout 2019-01-01, additionalneeds Breakfast | E3: PATCH | F3: {{baseUrl}}/booking/{{bookingid}} | G3: Cookie: token={{token}} Content-Type: application/json Accept: application/json | H3: {{requestBody}} = 데이터셋의 입력 body | I3: 상태 코드 == 데이터셋의 기대 Status | J3: GET {{baseUrl}}/booking/{{bookingid}} | K3: 기대 200: 원본에 보낸 필드를 덮어쓴 값 == 저장값 (bookingdates는 안쪽 필드까지 합침) 기대 400: 원본 == 저장값 | L3: data/patch-cases.json | M3: 부분수정_데이터 | N3: =COUNTA(부분수정_데이터!$A$2:$A$200) -> 33 | O3: 07-Data-Driven-Patch > Auth → PATCH 용 예약생성 → PATCH → 수정 후 재조회 → 예약 삭제 (정리) | P3: 예약생성: originalBooking 비움 PATCH: 행의 body → JSON.stringify → requestBody 변수 저장 | Q3: 예약생성: 상태 200 판정, bookingid(environment)·원본(variables) 저장 PATCH: 상태 코드 == expectedStatus 판정 재조회: 판정 기준(저장값)대로 비교, 다르면 기대·실제 로그 예약 삭제: 상태 200·201·204 판정 (테스트 데이터 정리) | R3: npm run test:data-patch

Sheet 예약생성_데이터
A1: ID | B1: 템플릿 | C1: 분류 | D1: 대상 | E1: 케이스 | F1: 테스트 목적 | G1: 입력 body | H1: 기대 Status | I1: 기대 Response | J1: 기대 저장값 | K1: 실제 Status | L1: 실제 Response / 저장값 | M1: 결과 | N1: 결함 ID | O1: 비고 | P1: 데이터 행
A2: BKG-POST-001 | B2: BKG-POST | C2: 정상 생성 | D2: 전체 필드 | E2: 정상 생성 | F2: 모든 필드를 정상 값으로 보내면 예약이 생성되는지 확인 | G2: { "firstname": "Kim", "lastname": "QA1", "totalprice": 990, "depositpaid": true, "bookingdates": { "checkin": "2026-10-20", "checkout": "2026-11-01" }, "additionalneeds": "brunch & liquor" } | H2: 200 | I2: bookingid 발급, booking = 보낸 값 | J2: - | K2: 200 | L2: 기대결과와 동일 | M2: PASS | P2: 1
A3: BKG-POST-002 | B3: BKG-POST | C3: 범위 검증 | D3: totalprice 경계값 | E3: 가격 경계값 1 | F3: 가격 최솟값 1로 예약이 생성되는지 확인 | G3: { "firstname": "Kim", "lastname": "QA2", "totalprice": 1, "depositpaid": true, "bookingdates": { "checkin": "2026-10-20", "checkout": "2026-11-01" }, "additionalneeds": "Allergic to orange" } | H3: 200 | I3: bookingid 발급, booking = 보낸 값 | J3: - | K3: 200 | L3: 기대결과와 동일 | M3: PASS | P3: 2
A4: BKG-POST-003 | B4: BKG-POST | C4: 범위 검증 | D4: totalprice 음수 | E4: 가격 음수 | F4: 음수 가격으로는 예약 생성이 거절되는지 확인 | G4: { "firstname": "Kim", "lastname": "QA3", "totalprice": -990, "depositpaid": true, "bookingdates": { "checkin": "2026-10-20", "checkout": "2026-11-01" }, "additionalneeds": "brunch & liquor" } | H4: 400 | I4: 에러 응답, 예약 미생성 | J4: - | K4: 200 | L4: bookingid 발급, totalprice -990 저장 | M4: FAIL | N4: Bug-2 | P4: 3
A5: BKG-POST-004 | B5: BKG-POST | C5: 타입 검증 | D5: totalprice 문자 섞임 | E5: 가격에 문자열 포함 | F5: 숫자와 문자가 섞인 가격으로는 예약 생성이 거절되는지 확인 | G5: { "firstname": "Kim", "lastname": "QA4", "totalprice": "9ㅁ90", "depositpaid": true, "bookingdates": { "checkin": "2026-10-20", "checkout": "2026-11-01" }, "additionalneeds": "brunch & liquor" } | H5: 400 | I5: 에러 응답, 예약 미생성 | J5: - | K5: 200 | L5: bookingid 발급, 예약 생성됨 | M5: FAIL | N5: Bug-10 | O5: Bug-10과 같은 유형 | P5: 4
A6: BKG-POST-005 | B6: BKG-POST | C6: 필수값 검증 | D6: firstname 누락 | E6: first name 누락 | F6: 필수값 firstname이 없으면 400으로 거절되는지 확인 | G6: { "lastname": "QA5", "totalprice": 990, "depositpaid": true, "bookingdates": { "checkin": "2026-10-20", "checkout": "2026-11-01" }, "additionalneeds": "brunch & liquor" } | H6: 400 | I6: 에러 응답, 예약 미생성 | J6: - | K6: 500 | L6: 에러 응답 | M6: FAIL | N6: Bug-5 | P6: 5
A7: BKG-POST-006 | B7: BKG-POST | C7: 날짜 검증 | D7: 체크인·아웃 역전 | E7: 체크인*아웃 날짜 역전 | F7: 체크아웃이 체크인보다 이전이면 예약 생성이 거절되는지 확인 | G7: { "firstname": "Kim", "lastname": "QA6", "totalprice": 990, "depositpaid": true, "bookingdates": { "checkin": "2026-11-20", "checkout": "2026-11-01" }, "additionalneeds": "brunch & liquor" } | H7: 400 | I7: 에러 응답, 예약 미생성 | J7: - | K7: 200 | L7: bookingid 발급, 역전된 날짜 그대로 저장 | M7: FAIL | N7: Bug-6 | P7: 6
A8: BKG-POST-007 | B8: BKG-POST | C8: 날짜 검증 | D8: checkin 형식 오류 | E8: 체크인 형식 오류 | F8: 날짜가 아닌 형식의 체크인으로는 예약 생성이 거절되는지 확인 | G8: { "firstname": "Kim", "lastname": "QA7", "totalprice": 990, "depositpaid": true, "bookingdates": { "checkin": "26th Oct 2026", "checkout": "2026-11-01" }, "additionalneeds": "brunch & liquor" } | H8: 400 | I8: 에러 응답, 예약 미생성 | J8: - | K8: 200 | L8: bookingid 발급, checkin 0NaN-aN-aN 저장 | M8: FAIL | N8: Bug-7 | P8: 7
A9: BKG-POST-008 | B9: BKG-POST | C9: 타입 검증 | D9: depositpaid 문자열 true | E9: depositpaid 문자열 | F9: boolean 필드에 문자열 "true"를 보내면 거절되는지 확인 | G9: { "firstname": "Kim", "lastname": "QA8", "totalprice": 990, "depositpaid": "true", "bookingdates": { "checkin": "2026-10-20", "checkout": "2026-11-01" }, "additionalneeds": "brunch & liquor" } | H9: 400 | I9: 에러 응답, 예약 미생성 | J9: - | K9: 200 | L9: bookingid 발급, depositpaid true 저장 | M9: FAIL | N9: D-1 | O9: 명세 외 타입 허용 | P9: 8
A10: BKG-POST-009 | B10: BKG-POST | C10: 타입 검증 | D10: depositpaid 문자열 false | E10: depositpaid 문자열 false값 | F10: boolean 필드에 문자열 "false"를 보내면 거절되는지 확인 | G10: { "firstname": "Kim", "lastname": "QA9", "totalprice": 990, "depositpaid": "false", "bookingdates": { "checkin": "2026-10-20", "checkout": "2026-11-01" }, "additionalneeds": "brunch & liquor" } | H10: 400 | I10: 에러 응답, 예약 미생성 | J10: - | K10: 200 | L10: bookingid 발급, depositpaid true 저장 | M10: FAIL | N10: D-2 | O10: 보낸 의미와 반대 값으로 저장됨 | P10: 9

Sheet 부분수정_데이터
A1: ID | B1: 템플릿 | C1: 분류 | D1: 대상 | E1: 케이스 | F1: 테스트 목적 | G1: 입력 body | H1: 기대 Status | I1: 기대 Response | J1: 기대 저장값 | K1: 실제 Status | L1: 실제 Response / 저장값 | M1: 결과 | N1: 결함 ID | O1: 비고 | P1: 데이터 행
A2: BKG-PATCH-001 | B2: BKG-PATCH | C2: 정상 수정 | D2: 전체 필드 A | E2: [전체] 모든 필드 정상 수정 A | F2: 모든 필드를 정상 값으로 수정하면 보낸 값으로 저장되는지 확인 | G2: { "firstname": "KimPatch", "lastname": "QA", "totalprice": 8990, "depositpaid": true, "bookingdates": { "checkin": "2026-10-20", "checkout": "2026-11-01" }, "additionalneeds": "brunch & liquor PATCH" } | H2: 200 | I2: 수정된 booking 반환 | J2: firstname = "KimPatch", lastname = "QA", totalprice = 8990, depositpaid = true, checkin = 2026-10-20, checkout = 2026-11-01, additionalneeds = "brunch & liquor PATCH"로 변경, 나머지는 원본 유지 | K2: 200 | L2: 기대결과와 동일 | M2: PASS | P2: 1
A3: BKG-PATCH-002 | B3: BKG-PATCH | C3: 정상 수정 | D3: 전체 필드 B | E3: [전체] 모든 필드 정상 수정 B (deposit false) | F3: 모든 필드를 다른 정상 값(depositpaid false 포함)으로 수정하면 보낸 값으로 저장되는지 확인 | G3: { "firstname": "Lee", "lastname": "Tester", "totalprice": 1, "depositpaid": false, "bookingdates": { "checkin": "2026-12-24", "checkout": "2026-12-26" }, "additionalneeds": "Allergic to orange" } | H3: 200 | I3: 수정된 booking 반환 | J3: firstname = "Lee", lastname = "Tester", totalprice = 1, depositpaid = false, checkin = 2026-12-24, checkout = 2026-12-26, additionalneeds = "Allergic to orange"로 변경, 나머지는 원본 유지 | K3: 200 | L3: 기대결과와 동일 | M3: PASS | P3: 2
A4: BKG-PATCH-003 | B4: BKG-PATCH | C4: 정상 수정 | D4: firstname | E4: [단일] firstname만 수정 | F4: firstname만 보내면 firstname만 바뀌고 나머지는 유지되는지 확인 | G4: { "firstname": "KimPatch" } | H4: 200 | I4: 수정된 booking 반환 | J4: firstname = "KimPatch"로 변경, 나머지는 원본 유지 | K4: 200 | L4: 기대결과와 동일 | M4: PASS | P4: 3
A5: BKG-PATCH-004 | B5: BKG-PATCH | C5: 정상 수정 | D5: lastname | E5: [단일] lastname만 수정 | F5: lastname만 보내면 lastname만 바뀌고 나머지는 유지되는지 확인 | G5: { "lastname": "QA" } | H5: 200 | I5: 수정된 booking 반환 | J5: lastname = "QA"로 변경, 나머지는 원본 유지 | K5: 200 | L5: 기대결과와 동일 | M5: PASS | P5: 4
A6: BKG-PATCH-005 | B6: BKG-PATCH | C6: 정상 수정 | D6: totalprice | E6: [단일] totalprice만 수정 | F6: totalprice만 보내면 totalprice만 바뀌고 나머지는 유지되는지 확인 | G6: { "totalprice": 8990 } | H6: 200 | I6: 수정된 booking 반환 | J6: totalprice = 8990로 변경, 나머지는 원본 유지 | K6: 200 | L6: 기대결과와 동일 | M6: PASS | P6: 5
A7: BKG-PATCH-006 | B7: BKG-PATCH | C7: 정상 수정 | D7: totalprice 경계값 | E7: [단일] totalprice 경계값 1 | F7: 가격 최솟값 1로 수정되는지 확인 | G7: { "totalprice": 1 } | H7: 200 | I7: 수정된 booking 반환 | J7: totalprice = 1로 변경, 나머지는 원본 유지 | K7: 200 | L7: 기대결과와 동일 | M7: PASS | P7: 6
A8: BKG-PATCH-007 | B8: BKG-PATCH | C8: 정상 수정 | D8: depositpaid | E8: [단일] depositpaid만 false로 수정 | F8: depositpaid만 false로 보내면 depositpaid만 바뀌는지 확인 | G8: { "depositpaid": false } | H8: 200 | I8: 수정된 booking 반환 | J8: depositpaid = false로 변경, 나머지는 원본 유지 | K8: 200 | L8: 기대결과와 동일 | M8: PASS | P8: 7
A9: BKG-PATCH-008 | B9: BKG-PATCH | C9: 정상 수정 | D9: bookingdates 전체 | E9: [단일] bookingdates 전체 수정 | F9: checkin·checkout을 함께 보내면 두 날짜만 바뀌는지 확인 | G9: { "bookingdates": { "checkin": "2018-06-01", "checkout": "2018-06-10" } } | H9: 200 | I9: 수정된 booking 반환 | J9: checkin = 2018-06-01, checkout = 2018-06-10로 변경, 나머지는 원본 유지 | K9: 200 | L9: 기대결과와 동일 | M9: PASS | P9: 8
A10: BKG-PATCH-009 | B10: BKG-PATCH | C10: 정상 수정 | D10: additionalneeds | E10: [단일] additionalneeds만 수정 | F10: additionalneeds만 보내면 additionalneeds만 바뀌는지 확인 | G10: { "additionalneeds": "Late checkout" } | H10: 200 | I10: 수정된 booking 반환 | J10: additionalneeds = "Late checkout"로 변경, 나머지는 원본 유지 | K10: 200 | L10: 기대결과와 동일 | M10: PASS | P10: 9
A11: BKG-PATCH-010 | B11: BKG-PATCH | C11: 타입 검증 | D11: firstname 숫자 | E11: [타입] firstname 숫자 | F11: 문자열 필드 firstname에 숫자를 보내면 수정이 거절되는지 확인 | G11: { "firstname": 123 } | H11: 400 | I11: 에러 응답 (수정되지 않음) | J11: 원본과 동일 | K11: 200 | L11: firstname = 123 (숫자) 저장 | M11: FAIL | N11: P-3 | P11: 10
A12: BKG-PATCH-011 | B12: BKG-PATCH | C12: 타입 검증 | D12: lastname boolean | E12: [타입] lastname boolean | F12: 문자열 필드 lastname에 boolean을 보내면 수정이 거절되는지 확인 | G12: { "lastname": true } | H12: 400 | I12: 에러 응답 (수정되지 않음) | J12: 원본과 동일 | K12: 200 | L12: lastname = true (boolean) 저장 | M12: FAIL | N12: P-3 | P12: 11
A13: BKG-PATCH-012 | B13: BKG-PATCH | C13: 타입 검증 | D13: totalprice 숫자 문자열 | E13: [타입] totalprice 숫자 문자열 | F13: 숫자 필드 totalprice에 숫자 문자열을 보내면 수정이 거절되는지 확인 | G13: { "totalprice": "990" } | H13: 400 | I13: 에러 응답 (수정되지 않음) | J13: 원본과 동일 | K13: 200 | L13: totalprice = 990 (숫자로 변환) 저장 | M13: FAIL | N13: P-4 | P13: 12
A14: BKG-PATCH-013 | B14: BKG-PATCH | C14: 타입 검증 | D14: totalprice 문자 섞임 | E14: [타입] totalprice 문자 섞임 | F14: totalprice에 숫자와 문자가 섞인 값을 보내면 수정이 거절되는지 확인 | G14: { "totalprice": "9ㅁ90" } | H14: 400 | I14: 에러 응답 (수정되지 않음) | J14: 원본과 동일 | K14: 200 | L14: totalprice = 9 (잘려 저장) | M14: FAIL | N14: P-5 | P14: 13
A15: BKG-PATCH-014 | B15: BKG-PATCH | C15: 타입 검증 | D15: depositpaid 문자열 true | E15: [타입] depositpaid 문자열 true | F15: boolean 필드에 문자열 "true"를 보내면 수정이 거절되는지 확인 | G15: { "depositpaid": "true" } | H15: 400 | I15: 에러 응답 (수정되지 않음) | J15: 원본과 동일 | K15: 200 | L15: depositpaid 원본(true) 유지 | M15: FAIL | N15: P-13 | O15: 정책 확인 필요: 400으로 거절할지, 무시하고 200을 줄지. 원본이 true라 무시와 변환이 구분되지 않음 | P15: 14
A16: BKG-PATCH-015 | B16: BKG-PATCH | C16: 타입 검증 | D16: depositpaid 문자열 false | E16: [타입] depositpaid 문자열 false | F16: boolean 필드에 문자열 "false"를 보내면 수정이 거절되는지 확인 | G16: { "depositpaid": "false" } | H16: 400 | I16: 에러 응답 (수정되지 않음) | J16: 원본과 동일 | K16: 200 | L16: depositpaid 원본(true) 유지 | M16: FAIL | N16: P-13 | O16: 정책 확인 필요: 400으로 거절할지, 무시하고 200을 줄지 | P16: 15
A17: BKG-PATCH-016 | B17: BKG-PATCH | C17: 타입 검증 | D17: depositpaid 숫자 0 | E17: [타입] depositpaid 숫자 0 | F17: boolean 필드에 숫자 0을 보내면 수정이 거절되는지 확인 | G17: { "depositpaid": 0 } | H17: 400 | I17: 에러 응답 (수정되지 않음) | J17: 원본과 동일 | K17: 200 | L17: depositpaid = false (변환) 저장 | M17: FAIL | N17: P-7 | O17: 문자열은 무시, 숫자는 변환되어 타입마다 처리가 다름 | P17: 16
A18: BKG-PATCH-017 | B18: BKG-PATCH | C18: 타입 검증 | D18: bookingdates 문자열 | E18: [타입] bookingdates 문자열 | F18: 객체 필드 bookingdates에 문자열을 보내면 수정이 거절되는지 확인 | G18: { "bookingdates": "2026-10-20" } | H18: 400 | I18: 에러 응답 (수정되지 않음) | J18: 원본과 동일 | K18: 200 | L18: checkin = 0NaN-aN-aN, checkout = 0NaN-aN-aN | M18: FAIL | N18: P-9 | P18: 17
A19: BKG-PATCH-018 | B19: BKG-PATCH | C19: 타입 검증 | D19: additionalneeds 숫자 | E19: [타입] additionalneeds 숫자 | F19: 문자열 필드 additionalneeds에 숫자를 보내면 수정이 거절되는지 확인 | G19: { "additionalneeds": 100 } | H19: 400 | I19: 에러 응답 (수정되지 않음) | J19: 원본과 동일 | K19: 200 | L19: additionalneeds = 100 (숫자) 저장 | M19: FAIL | N19: P-3 | P19: 18
A20: BKG-PATCH-019 | B20: BKG-PATCH | C20: 범위 검증 | D20: totalprice -1 | E20: [음수] totalprice -1 (경계값) | F20: 음수 경계값 -1로는 수정이 거절되는지 확인 | G20: { "totalprice": -1 } | H20: 400 | I20: 에러 응답 (수정되지 않음) | J20: 원본과 동일 | K20: 200 | L20: totalprice = -1 저장 | M20: FAIL | N20: P-6 | O20: Bug-3과 같은 유형 | P20: 19
A21: BKG-PATCH-020 | B21: BKG-PATCH | C21: 범위 검증 | D21: totalprice -990 | E21: [음수] totalprice -990 | F21: 음수 가격으로는 수정이 거절되는지 확인 | G21: { "totalprice": -990 } | H21: 400 | I21: 에러 응답 (수정되지 않음) | J21: 원본과 동일 | K21: 200 | L21: totalprice = -990 저장 | M21: FAIL | N21: P-6 | O21: Bug-3과 같은 유형 | P21: 20
A22: BKG-PATCH-021 | B22: BKG-PATCH | C22: 날짜 검증 | D22: 날짜 역전 (둘 다) | E22: [날짜] 역전 - 둘 다 보냄 | F22: 체크아웃이 체크인보다 이전이 되도록 두 날짜를 보내면 거절되는지 확인 | G22: { "bookingdates": { "checkin": "2026-11-20", "checkout": "2026-11-01" } } | H22: 400 | I22: 에러 응답 (수정되지 않음) | J22: 원본과 동일 | K22: 200 | L22: checkin = 2026-11-20, checkout = 2026-11-01 (역전된 채로) 저장 | M22: FAIL | N22: P-8 | P22: 21
A23: BKG-PATCH-022 | B23: BKG-PATCH | C23: 날짜 검증 | D23: 날짜 역전 (checkout만) | E23: [날짜] 역전 - checkout만 보내 기존 checkin보다 이전 | F23: checkout만 기존 checkin(2018-01-01)보다 이전으로 보내면 거절되는지 확인 | G23: { "bookingdates": { "checkout": "2017-12-31" } } | H23: 400 | I23: 에러 응답 (수정되지 않음) | J23: 원본과 동일 | K23: 200 | L23: checkin = 0NaN-aN-aN, checkout = 2017-12-31 | M23: FAIL | N23: P-2 | O23: 보내지 않은 checkin이 깨짐 | P23: 22
A24: BKG-PATCH-023 | B24: BKG-PATCH | C24: 날짜 검증 | D24: checkin 구분자 없음 | E24: [날짜] 형식 오류 - 구분자 없음 | F24: 구분자 없는 날짜(20180101)로는 수정이 거절되는지 확인 | G24: { "bookingdates": { "checkin": "20180101", "checkout": "2019-01-01" } } | H24: 400 | I24: 에러 응답 (수정되지 않음) | J24: 원본과 동일 | K24: 200 | L24: checkin = 0NaN-aN-aN, checkout = 2019-01-01 | M24: FAIL | N24: P-9 | P24: 23
A25: BKG-PATCH-024 | B25: BKG-PATCH | C25: 날짜 검증 | D25: checkin 실사용 형식 | E25: [날짜] 형식 오류 - 실사용 형식 | F25: "26th Oct 2026" 형식으로는 수정이 거절되는지 확인 | G25: { "bookingdates": { "checkin": "26th Oct 2026", "checkout": "2026-11-01" } } | H25: 400 | I25: 에러 응답 (수정되지 않음) | J25: 원본과 동일 | K25: 200 | L25: checkin = 0NaN-aN-aN, checkout = 2026-11-01 | M25: FAIL | N25: P-9 | P25: 24
A26: BKG-PATCH-025 | B26: BKG-PATCH | C26: 날짜 검증 | D26: checkin 13월 | E26: [날짜] 없는 날짜 - 13월 | F26: 존재하지 않는 월(13월)로는 수정이 거절되는지 확인 | G26: { "bookingdates": { "checkin": "2026-13-01", "checkout": "2026-12-01" } } | H26: 400 | I26: 에러 응답 (수정되지 않음) | J26: 원본과 동일 | K26: 200 | L26: checkin = 0NaN-aN-aN, checkout = 2026-12-01 | M26: FAIL | N26: P-9 | P26: 25
A27: BKG-PATCH-026 | B27: BKG-PATCH | C27: 날짜 검증 | D27: checkin 2월 30일 | E27: [날짜] 없는 날짜 - 2월 30일 | F27: 존재하지 않는 날짜(2월 30일)로는 수정이 거절되는지 확인 | G27: { "bookingdates": { "checkin": "2026-02-30", "checkout": "2026-03-05" } } | H27: 400 | I27: 에러 응답 (수정되지 않음) | J27: 원본과 동일 | K27: 200 | L27: checkin = 2026-03-02, checkout = 2026-03-05 | M27: FAIL | N27: P-10 | O27: 없는 날짜가 다음 달로 넘어가 저장됨 | P27: 26
A28: BKG-PATCH-027 | B28: BKG-PATCH | C28: 날짜 검증 | D28: checkin 빈 문자열 | E28: [날짜] 빈 문자열 | F28: 빈 문자열 날짜로는 수정이 거절되는지 확인 | G28: { "bookingdates": { "checkin": "", "checkout": "2019-01-01" } } | H28: 400 | I28: 에러 응답 (수정되지 않음) | J28: 원본과 동일 | K28: 200 | L28: checkin = 0NaN-aN-aN, checkout = 2019-01-01 | M28: FAIL | N28: P-9 | P28: 27
A29: BKG-PATCH-028 | B29: BKG-PATCH | C29: 정상 수정 | D29: checkin만 수정 | E29: [추가] bookingdates 중 checkin만 수정 | F29: bookingdates에 checkin만 보내면 checkin만 바뀌고 checkout은 유지되는지 확인 | G29: { "bookingdates": { "checkin": "2018-06-01" } } | H29: 200 | I29: 수정된 booking 반환 | J29: checkin = 2018-06-01로 변경, checkout(2019-01-01) 등 나머지는 원본 유지 | K29: 200 | L29: checkin = 2018-06-01, checkout = 0NaN-aN-aN | M29: FAIL | N29: P-1 | O29: 정상 요청에서 보내지 않은 필드가 깨짐 | P29: 28
A30: BKG-PATCH-029 | B30: BKG-PATCH | C30: 요청 형식 검증 | D30: 빈 body | E30: [추가] 빈 body | F30: 수정할 필드가 없는 빈 body는 거절되는지 확인 | G30: {} | H30: 400 | I30: 에러 응답 (수정되지 않음) | J30: 원본과 동일 | K30: 200 | L30: 원본 유지 | M30: FAIL | N30: P-14 | P30: 29
A31: BKG-PATCH-030 | B31: BKG-PATCH | C31: 요청 형식 검증 | D31: firstname null | E31: [추가] null 값 | F31: firstname에 null을 보내면 수정이 거절되는지 확인 | G31: { "firstname": null } | H31: 400 | I31: 에러 응답 (수정되지 않음) | J31: 원본과 동일 | K31: 200 | L31: firstname = null 저장 | M31: FAIL | N31: P-11 | P31: 30
A32: BKG-PATCH-031 | B32: BKG-PATCH | C32: 요청 형식 검증 | D32: firstname 빈 문자열 | E32: [추가] 빈 문자열 이름 (정책) | F32: firstname에 빈 문자열을 보내면 수정이 거절되는지 확인 | G32: { "firstname": "" } | H32: 400 | I32: 에러 응답 (수정되지 않음) | J32: 원본과 동일 | K32: 200 | L32: firstname = "" (빈 문자열) 저장 | M32: FAIL | N32: P-12 | O32: 정책 확인 필요: 빈 이름 허용 여부 | P32: 31
A33: BKG-PATCH-032 | B33: BKG-PATCH | C33: 요청 형식 검증 | D33: 필드명 대문자 | E33: [추가] 필드명 대문자만 | F33: 명세에 없는 대소문자 필드명(Firstname, TotalPrice)은 거절되는지 확인 | G33: { "Firstname": "Kim", "TotalPrice": 990 } | H33: 400 | I33: 에러 응답 (수정되지 않음) | J33: 원본과 동일 | K33: 200 | L33: 원본 유지 | M33: FAIL | N33: P-14 | P33: 32
A34: BKG-PATCH-033 | B34: BKG-PATCH | C34: 요청 형식 검증 | D34: 정의되지 않은 필드 | E34: [추가] 정의되지 않은 필드만 | F34: 명세에 없는 필드(discount)만 보내면 거절되는지 확인 | G34: { "discount": 50 } | H34: 400 | I34: 에러 응답 (수정되지 않음) | J34: 원본과 동일 | K34: 200 | L34: 원본 유지 | M34: FAIL | N34: P-14 | P34: 33

Sheet 결함목록
A1: 결함 ID | B1: API | C1: 내용 | D1: 관련 케이스 | E1: 심각도 | F1: 상태
A2: Bug-2 | B2: POST /booking | C2: 음수 가격이 그대로 저장됨 | D2: BKG-POST-003 | E2: 상 | F2: Open
A3: Bug-5 | B3: POST /booking | C3: 필수값 firstname 누락 시 400이 아니라 500 반환 | D3: BKG-POST-005 | E3: 중 | F3: Open
A4: Bug-6 | B4: POST /booking | C4: 체크아웃이 체크인보다 이전이어도 그대로 저장됨 | D4: BKG-POST-006 | E4: 상 | F4: Open
A5: Bug-7 | B5: POST /booking | C5: 날짜가 아닌 체크인 값이 0NaN-aN-aN으로 저장됨 | D5: BKG-POST-007 | E5: 상 | F5: Open
A6: Bug-10 | B6: POST /booking | C6: 숫자와 문자가 섞인 가격을 거절하지 않음 | D6: BKG-POST-004 | E6: 상 | F6: Open
A7: D-1 | B7: POST /booking | C7: depositpaid 문자열 "true"를 boolean true로 변환해 저장 | D7: BKG-POST-008 | E7: 중 | F7: Open
A8: D-2 | B8: POST /booking | C8: depositpaid 문자열 "false"를 true로 저장 (의미 반전) | D8: BKG-POST-009 | E8: 상 | F8: Open
A9: P-1 | B9: PATCH /booking/{id} | C9: bookingdates에 checkin만 보내면 checkout이 0NaN-aN-aN으로 바뀜 | D9: BKG-PATCH-028 | E9: 상 | F9: Open
A10: P-2 | B10: PATCH /booking/{id} | C10: bookingdates에 checkout만 보내면 checkin이 0NaN-aN-aN으로 바뀜 | D10: BKG-PATCH-022 | E10: 상 | F10: Open
A11: P-3 | B11: PATCH /booking/{id} | C11: 문자열 필드에 숫자·boolean이 그대로 저장됨 | D11: BKG-PATCH-010, 011, 018 | E11: 상 | F11: Open
A12: P-4 | B12: PATCH /booking/{id} | C12: totalprice 숫자 문자열을 숫자로 변환해 저장 | D12: BKG-PATCH-012 | E12: 중 | F12: Open
... A22: P-14 | B22: PATCH /booking/{id} | C22: 수정할 필드가 없는 요청도 200 반환 | D22: BKG-PATCH-029, 032, 033 | E22: 하 | F22: Open
